Workbook

Sheet Cover
B2: ANOH GAS PROCESSING PLANT
B3: Project Finance, Debt Capacity & Commodity Risk Model
B4: ANOH Gas Processing Company Limited (AGPC) - OML 53, Imo State, Nigeria
B6: PROJECT SUMMARY
B7: Project company | C7: ANOH Gas Processing Company Limited (AGPC)
B8: Ownership | C8: Seplat Energy Plc 50% / Nigerian Gas Infrastructure Company (NGIC) 50%
B9: Asset | C9: 300 MMscfd integrated gas processing plant (2 x 150 MMscfd trains), LPG recovery, condensate stabilisation, 16 MW captive power
B10: Location | C10: OML 53 (unitised with OML 21), Imo State, Nigeria
B11: Original funding | C11: US$420m combined equity + US$260m senior debt (closed February 2021)
B12: Additional funding | C12: US$40m combined equity (H1 2025) + US$30m Vitol prepayment facility (Q3 2025)
B13: Original first gas guidance | C13: Q4 2021
B14: Actual first gas | C14: 16 January 2026
B15: Current run-rate | C15: 50-70 MMscfd processed gas to Indorama; condensate 2.0-2.5 kboepd
B16: Modelling perimeter | C16: AGPC as project SPV, with a look-through bridge to Seplat Energy Plc
B18: CONTENTS
B19: 1. Cover | C19: Title, project summary, colour key and disclaimer
B20: 2. Assumptions Register | C20: Every input classified Disclosed / Derived / Estimated, with source
B21: 3. Inputs | C21: All model assumptions and the live scenario selector
B22: 4. Timeline | C22: Semi-annual periods H1 2020 - H2 2037 and period flags
B23: 5. Construction & Funding | C23: Sources and uses, drawdown profile, IDC and the 2021-2026 delay bridge
B24: 6-17 (to build) | C24: Throughput, pricing, opex, tax, cash waterfall, debt, ratios, returns, sensitivities, breakeven, dashboard, checks
B26: COLOUR KEY
B27: Blue text | C27: Hardcoded input or scenario lever - edit these
B28: Black text | C28: Formula calculated on this sheet - do not overwrite
B29: Green text | C29: Link to another sheet in this workbook
B30: Yellow fill | C30: Key assumption or scenario switch
B32: IMPORTANT NOTICE
B33: Disclaimer | C33: This model is an independent, illustrative analytical exercise prepared from publicly available information for portfolio and educational purposes only. It is not investment, financial or legal advice, is not a recommendation to buy, sell or hold any security, and is not affiliated with, endorsed by or prepared on behalf of Seplat Energy Plc, ANOH Gas Processing Company Limited, the Nigerian Gas Infrastructure Company or any of their affiliates. Project-level data for AGPC is only partly disclosed. Debt pricing and tenor, gas sales pricing, feedstock cost, product yields and the operating cost base are NOT public and have been estimated. Every input is classified on the Assumptions Register as Disclosed, Derived or Estimated. Conclusions should be read as sensitivities around estimated inputs, not as statements of fact about the project's financial position.
B35: Prepared by | C35: Yusuf Zayyad Aliyu | Project finance & credit risk modelling | Abuja, Nigeria
B36: Version | C36: v0.1 - Tabs 1-5 (Cover, Register, Inputs, Timeline, Construction & Funding)
B37: Base information date | C37: Seplat Energy FY2025 audited results (26 February 2026) and earlier filings

Sheet Assumptions Register
B2: ASSUMPTIONS REGISTER
B3: Every material input, classified by evidential status. Disclosed = stated in a public filing or release. Derived = calculated from disclosed figures. Estimated = analyst assumption, not public.
B6: Ref | C6: Assumption | D6: Value | E6: Unit | F6: Class | G6: Source | H6: Source date
B7: P.04 | C7: Seplat Energy ownership of AGPC | D7: 0.5 | E7: % | F7: Disclosed | G7: Seplat RNS 'ANOH Gas Project Achieves First Gas', 20 Jan 2026 | H7: 20-Jan-2026
B8: P.05 | C8: NGIC ownership of AGPC | D8: 0.5 | E8: % | F8: Disclosed | G8: Seplat RNS 'ANOH Gas Project Achieves First Gas', 20 Jan 2026 | H8: 20-Jan-2026
B9: P.06 | C9: Seplat working interest in OML 53 (upstream) | D9: 0.4 | E9: % | F9: Disclosed | G9: Seplat FY2025 audited results, 26 Feb 2026 | H9: 26-Feb-2026
B10: C.01 | C10: Plant design capacity | D10: 300 | E10: MMscfd | F10: Disclosed | G10: Seplat Energy website - ANOH Gas Processing Plant page | H10: 2026
B11: C.02 | C11: Processing trains | D11: 2 | E11: # | F11: Disclosed | G11: Seplat RNS 'ANOH Gas Project Achieves First Gas', 20 Jan 2026 | H11: 20-Jan-2026
B12: C.03 | C12: Capacity per train | D12: 150 | E12: MMscfd | F12: Disclosed | G12: Seplat RNS 'ANOH Gas Project Achieves First Gas', 20 Jan 2026 | H12: 20-Jan-2026
B13: C.04 | C13: Plant availability (uptime) | D13: 0.92 | E13: % | F13: Estimated | G13: Analyst estimate - not publicly disclosed | H13: -
B14: C.05 | C14: Stabilised run-rate at first gas - low | D14: 50 | E14: MMscfd | F14: Disclosed | G14: Seplat FY2025 audited results, 26 Feb 2026 | H14: 26-Feb-2026
B15: C.06 | C15: Stabilised run-rate at first gas - high | D15: 70 | E15: MMscfd | F15: Disclosed | G15: Seplat FY2025 audited results, 26 Feb 2026 | H15: 26-Feb-2026
B16: C.07 | C16: Utilisation ramp profile (years 1-5) | E16: % | F16: Estimated | G16: Analyst estimate anchored on disclosed 50-70 MMscfd actual run-rate | H16: -
B17: O.01 | C17: Indorama firm offtake capacity | D17: 60 | E17: MMscfd | F17: Estimated | G17: Estimated from disclosed 50-70 MMscfd delivered under firm/interruptible GSAs | H17: -
B18: O.03 | C18: NLNG interruptible route capacity | D18: 80 | E18: MMscfd | F18: Estimated | G18: Analyst estimate - not publicly disclosed | H18: -
B19: O.04 | C19: OB3 domestic route capacity | D19: 140 | E19: MMscfd | F19: Estimated | G19: Balancing capacity to design; OB3 construction resumed, completion date not yet announced | H19: -
B20: R.01 | C20: Brent price assumption | D20: 65 | E20: $/bbl | F20: Disclosed | G20: Seplat 2026 cash tax guidance assumption | H20: 26-Feb-2026
B21: R.02 | C21: Dry gas realised price | D21: 2.75 | E21: $/Mscf | F21: Disclosed | G21: Seplat 2026 guidance gas price assumption ($2.95/Mscf realised FY2025) | H21: 26-Feb-2026
B22: R.04 | C22: Condensate differential to Brent | D22: -3 | E22: $/bbl | F22: Estimated | G22: Analyst estimate - not publicly disclosed | H22: -
B23: R.05 | C23: LPG price as % of Brent | D23: 0.6 | E23: % | F23: Derived | G23: Seplat FY2025 realised NGL price $45.14/bbl vs Brent $68.07/bbl (66%); discounted for LPG | H23: 26-Feb-2026
B24: R.06 | C24: Condensate yield | D24: 48 | E24: bbl/MMscf | F24: Derived | G24: 2.0-2.5 kboepd condensate at 40-52 MMscfd processed gas at first gas | H24: 20-Jan-2026
B25: R.07 | C25: LPG yield | D25: 8 | E25: bbl/MMscf | F25: Estimated | G25: Recovery is additional to the condensate stream; set low to avoid double counting liquids | H25: -
B26: X.01 | C26: Wet gas feedstock cost as % of total product revenue | D26: 0.55 | E26: % | F26: Estimated | G26: Transfer price from the OML 53 upstream JV to AGPC is not disclosed. Priced as a share of total product revenue because the wet stream carries the liquids value | H26: -
B27: X.02 | C27: Fixed O&M | D27: 35 | E27: $m p.a. | F27: Estimated | G27: Analyst estimate - not publicly disclosed | H27: -
B28: X.03 | C28: Variable O&M | D28: 0.15 | E28: $/Mscf | F28: Estimated | G28: Analyst estimate - not publicly disclosed | H28: -
... B38: D.12 | C38: Vitol facility margin over SOFR | D38: 0.1 | E38: % | F38: Disclosed | G38: Facility priced at SOFR plus 10% | H38: 26-Feb-2026
B39: T.03 | C39: Original first gas guidance | D39: Q4 2021 | E39: date | F39: Disclosed | G39: Seplat guidance as at Oct 2020 | H39: Oct-2020
B40: T.04 | C40: Actual first gas | D40: 16-Jan-2026 | E40: date | F40: Disclosed | G40: Seplat RNS 'ANOH Gas Project Achieves First Gas', 20 Jan 2026 | H40: 20-Jan-2026
B41: T.08 | C41: First principal repayment permitted | D41: 31-Mar-2026 | E41: date | F41: Disclosed | G41: AGPC commercial lenders waived principal repayment until the earlier of two quarters after completion or 31 March 2026 | H41: 30-Jul-2025
B42: E.01 | C42: Original equity - Seplat | D42: 210 | E42: $m | F42: Disclosed | G42: Seplat / AGPC debt close announcement, Feb 2021 | H42: Feb-2021
B43: E.02 | C43: Original equity - NGIC | D43: 210 | E43: $m | F43: Disclosed | G43: Seplat / AGPC debt close announcement, Feb 2021 | H43: Feb-2021
B44: E.03 | C44: Additional equity H1 2025 - Seplat | D44: 20 | E44: $m | F44: Disclosed | G44: $10m in Q1 2025 and $10m in Q2 2025 | H44: 30-Jul-2025
B45: E.04 | C45: Additional equity H1 2025 - NGIC | D45: 20 | E45: $m | F45: Disclosed | G45: Seplat 6M 2025 interim report, 30 Jul 2025 | H45: 30-Jul-2025
B46: E.07 | C46: Seplat carrying value of JV investment (cross-check) | D46: 398949 | E46: NGN m | F46: Disclosed | G46: Investment accounted for using equity method, 30 June 2025 (31 Dec 2024: NGN 374,641m) | H46: 30-Jul-2025
B47: M.01 | C47: USD/NGN reference rate | D47: 1550 | E47: NGN/USD | F47: Derived | G47: Implied from Seplat 6M 2025 dual-currency reporting | H47: 30-Jul-2025
B48: M.05 | C48: Project discount rate (WACC) | D48: 0.14 | E48: % | F48: Estimated | G48: Nigeria country risk adjusted; not a disclosed figure | H48: -
B50: COUNT | C50: Inputs classified Disclosed | D50: =COUNTIF($G$7:$G$48,"x")+COUNTIF($F$7:$F$48,"Disclosed")-COUNTIF($G$7:$G$48,"x") -> 22
C51: Inputs classified Derived | D51: =COUNTIF($F$7:$F$48,"Derived") -> 3
C52: Inputs classified Estimated | D52: =COUNTIF($F$7:$F$48,"Estimated") -> 17
B54: Note | C54: AGPC's own audited accounts are not published. Seplat consolidates its 50% interest under the equity method, so AGPC's revenue, opex, debt balance and interest cost are not separately visible in the group financial statements. Every Estimated line above is therefore a genuine analytical assumption and the model's conclusions are presented as breakeven and sensitivity results rather than point forecasts.

Sheet Inputs
B2: INPUTS & SCENARIO CONTROL
B3: Blue cells are inputs. Columns G:J hold the four headline scenarios; column D shows the live value for the selected scenario and is what the rest of the model reads.
C6: SCENARIO SELECTOR (1 = Base, 2 = Stalled ramp-up, 3 = OB3 never completes, 4 = Severe combined) | D6: 1 | E6: Active: | F6: =INDEX($G$8:$J$8,1,$D$6) -> S1 Base
B8: Ref | C8: Input | D8: Live value | E8: Unit | F8: Class | G8: S1 Base | H8: S2 Stalled | I8: S3 No OB3 | J8: S4 Severe | K8: Note
B9: 1. PROJECT & OWNERSHIP
B10: P.04 | C10: Seplat Energy ownership of AGPC | D10: 0.5 | E10: % | F10: Disclosed | K10: Incorporated JV, 50:50 with NGIC
B11: P.05 | C11: NGIC ownership of AGPC | D11: 0.5 | E11: % | F11: Disclosed
B12: P.06 | C12: Seplat working interest in OML 53 (upstream) | D12: 0.4 | E12: % | F12: Disclosed | K12: Drives the second Seplat revenue stream: wet gas sales into AGPC
B14: 2. TIMELINE
B15: T.01 | C15: Model start year | D15: 2020 | E15: year | F15: Estimated | K15: First modelled semi-annual period is H1 2020
B16: T.02 | C16: Number of semi-annual periods | D16: 36 | E16: # | F16: Estimated | K16: H1 2020 to H2 2037
B17: T.03 | C17: Original first gas guidance | D17: =DATE(2021,12,31) -> 44561 | E17: date | F17: Disclosed | K17: Q4 2021 guidance given in 2020
B18: T.04 | C18: Actual first gas date | D18: =DATE(2026,1,16) -> 46038 | E18: date | F18: Disclosed | K18: AGPC commenced gas supply to Indorama on 16 January 2026
B19: T.05 | C19: First operating period number | D19: 13 | E19: # | F19: Derived | K19: H1 2026
B20: T.06 | C20: Ramp-up duration | D20: =INDEX($G20:$J20,1,$D$6) -> 4 | E20: years | F20: Estimated | G20: 4 | H20: 6 | I20: 5 | J20: 6 | K20: Years from COD before steady-state utilisation
B21: T.07 | C21: Modelled operating life | D21: 12 | E21: years | F21: Estimated | K21: To H2 2037
B22: T.08 | C22: First principal repayment period number | D22: 14 | E22: # | F22: Disclosed | K22: Lenders waived principal repayment until the earlier of two quarters after completion or 31 March 2026; H2 2026 is the first modelled instalment
B23: T.09 | C23: Senior debt repayment periods | D23: 16 | E23: # | F23: Estimated | K23: Eight-year semi-annual amortisation from H2 2026
B25: 3. CAPACITY & THROUGHPUT
B26: C.01 | C26: Plant design capacity | D26: 300 | E26: MMscfd | F26: Disclosed | K26: Two 150 MMscfd trains
B27: C.04 | C27: Plant availability (uptime) | D27: 0.92 | E27: % | F27: Estimated
B28: C.05 | C28: Observed run-rate at first gas - low | D28: 50 | E28: MMscfd | F28: Disclosed | K28: FY2025 results: stable daily flow of 50-70 MMscfd to Indorama
B29: C.06 | C29: Observed run-rate at first gas - high | D29: 70 | E29: MMscfd | F29: Disclosed
B30: C.07 | C30: Utilisation - operating year 1 | D30: =INDEX($G30:$J30,1,$D$6) -> 0.2 | E30: % | F30: Estimated | G30: 0.2 | H30: 0.18 | I30: 0.2 | J30: 0.16 | K30: Base case year 1 approximates the disclosed 60 MMscfd mid-point
B31: C.08 | C31: Utilisation - operating year 2 | D31: =INDEX($G31:$J31,1,$D$6) -> 0.4 | E31: % | F31: Estimated | G31: 0.4 | H31: 0.2 | I31: 0.32 | J31: 0.18
B32: C.09 | C32: Utilisation - operating year 3 | D32: =INDEX($G32:$J32,1,$D$6) -> 0.6 | E32: % | F32: Estimated | G32: 0.6 | H32: 0.2 | I32: 0.42 | J32: 0.18
B33: C.10 | C33: Utilisation - operating year 4 | D33: =INDEX($G33:$J33,1,$D$6) -> 0.75 | E33: % | F33: Estimated | G33: 0.75 | H33: 0.2 | I33: 0.45 | J33: 0.18
B34: C.11 | C34: Utilisation - steady state | D34: =INDEX($G34:$J34,1,$D$6) -> 0.85 | E34: % | F34: Estimated | G34: 0.85 | H34: 0.2 | I34: 0.45 | J34: 0.18 | K34: Scenario 3 caps at the Indorama plus NLNG routes only
B36: 4. OFFTAKE ROUTES
B37: O.01 | C37: Indorama - firm offtake capacity | D37: 60 | E37: MMscfd | F37: Estimated | K37: Firm and interruptible GSAs in place; capacity split not disclosed
B38: O.02 | C38: Indorama - interruptible capacity | D38: 20 | E38: MMscfd | F38: Estimated
B39: O.03 | C39: NLNG - interruptible capacity | D39: 80 | E39: MMscfd | F39: Estimated | K39: Offtake structured on an interruptible basis; mechanical, commercial and regulatory requirements complete, awaiting clearance to flow
B40: O.04 | C40: OB3 pipeline - domestic route capacity | D40: 140 | E40: MMscfd | F40: Estimated | K40: Originally the primary channel to the domestic market
B41: O.05 | C41: NLNG route available from period number | D41: =INDEX($G41:$J41,1,$D$6) -> 14 | E41: # | F41: Estimated | G41: 14 | H41: 16 | I41: 14 | J41: 18 | K41: H2 2026 in the base case
B42: O.06 | C42: OB3 route available from period number | D42: =INDEX($G42:$J42,1,$D$6) -> 19 | E42: # | F42: Estimated | G42: 19 | H42: 21 | I42: 99 | J42: 99 | K42: H1 2029 base case. 99 = never within the model horizon. NGIC has resumed construction but has not announced a revised completion date
B43: O.07 | C43: Interruptible route availability factor | D43: =INDEX($G43:$J43,1,$D$6) -> 0.7 | E43: % | F43: Estimated | G43: 0.7 | H43: 0.6 | I43: 0.7 | J43: 0.5 | K43: Proportion of nameplate interruptible capacity assumed actually deliverable
B45: 5. PRICING
B46: R.01 | C46: Brent crude price | D46: =INDEX($G46:$J46,1,$D$6) -> 65 | E46: $/bbl | F46: Disclosed | G46: 65 | H46: 65 | I46: 65 | J46: 45 | K46: Seplat's own 2026 cash tax guidance assumption
B47: R.02 | C47: Dry gas realised price | D47: =INDEX($G47:$J47,1,$D$6) -> 2.75 | E47: $/Mscf | F47: Disclosed | G47: 2.75 | H47: 2.75 | I47: 2.75 | J47: 2.2 | K47: Seplat 2026 guidance assumption; FY2025 group realised $2.95/Mscf
B48: R.03 | C48: Gas price escalation p.a. | D48: 0.015 | E48: % | F48: Estimated
...

Sheet Timeline
B2: TIMELINE & PERIOD FLAGS
B3: Semi-annual periods from H1 2020 to H2 2037. Every downstream schedule keys off the flags below.
B6: PERIOD STRUCTURE
B7: t.01 | C7: Period number | H7: 1 | I7: 2 | J7: 3 | K7: 4 | L7: 5 | M7: 6 | N7: 7 | O7: 8 | P7: 9 | Q7: 10 | R7: 11 | S7: 12 | T7: 13 | U7: 14 | V7: 15 | W7: 16 | X7: 17 | Y7: 18 | Z7: 19 | AA7: 20 | AB7: 21 | AC7: 22 | AD7: 23 | AE7: 24 | AF7: 25 | AG7: 26 | AH7: 27 | AI7: 28 | AJ7: 29 | AK7: 30 | AL7: 31 | AM7: 32 | AN7: 33 | AO7: 34 | AP7: 35 | AQ7: 36
B8: t.02 | C8: Calendar year | H8: =Inputs!$D$15+INT((H7-1)/2) -> 2020 | I8: =Inputs!$D$15+INT((I7-1)/2) -> 2020 | J8: =Inputs!$D$15+INT((J7-1)/2) -> 2021 | K8: =Inputs!$D$15+INT((K7-1)/2) -> 2021 | L8: =Inputs!$D$15+INT((L7-1)/2) -> 2022 | M8: =Inputs!$D$15+INT((M7-1)/2) -> 2022 | N8: =Inputs!$D$15+INT((N7-1)/2) -> 2023 | O8: =Inputs!$D$15+INT((O7-1)/2) -> 2023 | ... AQ8: =Inputs!$D$15+INT((AQ7-1)/2) -> 2037
B9: t.03 | C9: Half | H9: =IF(MOD(H7,2)=1,1,2) -> 1 | I9: =IF(MOD(I7,2)=1,1,2) -> 2 | J9: =IF(MOD(J7,2)=1,1,2) -> 1 | K9: =IF(MOD(K7,2)=1,1,2) -> 2 | L9: =IF(MOD(L7,2)=1,1,2) -> 1 | M9: =IF(MOD(M7,2)=1,1,2) -> 2 | N9: =IF(MOD(N7,2)=1,1,2) -> 1 | O9: =IF(MOD(O7,2)=1,1,2) -> 2 | ... AQ9: =IF(MOD(AQ7,2)=1,1,2) -> 2
B10: t.04 | C10: Period label | H10: ="H"&H9&" "&TEXT(H8,"0") -> H1 2020 | I10: ="H"&I9&" "&TEXT(I8,"0") -> H2 2020 | J10: ="H"&J9&" "&TEXT(J8,"0") -> H1 2021 | K10: ="H"&K9&" "&TEXT(K8,"0") -> H2 2021 | L10: ="H"&L9&" "&TEXT(L8,"0") -> H1 2022 | M10: ="H"&M9&" "&TEXT(M8,"0") -> H2 2022 | N10: ="H"&N9&" "&TEXT(N8,"0") -> H1 2023 | O10: ="H"&O9&" "&TEXT(O8,"0") -> H2 2023 | ... AQ10: ="H"&AQ9&" "&TEXT(AQ8,"0") -> H2 2037
B11: t.05 | C11: Period start | H11: =DATE(H8,IF(H9=1,1,7),1) -> 43831 | I11: =DATE(I8,IF(I9=1,1,7),1) -> 44013 | J11: =DATE(J8,IF(J9=1,1,7),1) -> 44197 | K11: =DATE(K8,IF(K9=1,1,7),1) -> 44378 | L11: =DATE(L8,IF(L9=1,1,7),1) -> 44562 | M11: =DATE(M8,IF(M9=1,1,7),1) -> 44743 | N11: =DATE(N8,IF(N9=1,1,7),1) -> 44927 | O11: =DATE(O8,IF(O9=1,1,7),1) -> 45108 | ... AQ11: =DATE(AQ8,IF(AQ9=1,1,7),1) -> 50222
B12: t.06 | C12: Period end | H12: =EOMONTH(H11,5) -> 44012 | I12: =EOMONTH(I11,5) -> 44196 | J12: =EOMONTH(J11,5) -> 44377 | K12: =EOMONTH(K11,5) -> 44561 | L12: =EOMONTH(L11,5) -> 44742 | M12: =EOMONTH(M11,5) -> 44926 | N12: =EOMONTH(N11,5) -> 45107 | O12: =EOMONTH(O11,5) -> 45291 | ... AQ12: =EOMONTH(AQ11,5) -> 50405
B13: t.07 | C13: Days in period | H13: =H12-H11+1 -> 182 | I13: =I12-I11+1 -> 184 | J13: =J12-J11+1 -> 181 | K13: =K12-K11+1 -> 184 | L13: =L12-L11+1 -> 181 | M13: =M12-M11+1 -> 184 | N13: =N12-N11+1 -> 181 | O13: =O12-O11+1 -> 184 | ... AQ13: =AQ12-AQ11+1 -> 184
B14: t.08 | C14: Year fraction | H14: =H13/365 -> 0.49863014 | I14: =I13/365 -> 0.50410959 | J14: =J13/365 -> 0.49589041 | K14: =K13/365 -> 0.50410959 | L14: =L13/365 -> 0.49589041 | M14: =M13/365 -> 0.50410959 | N14: =N13/365 -> 0.49589041 | O14: =O13/365 -> 0.50410959 | ... AQ14: =AQ13/365 -> 0.50410959
B16: PROJECT PHASE FLAGS (1 = active)
B17: t.10 | C17: Construction phase | H17: =IF(H7<Inputs!$D$19,1,0) -> 1 | I17: =IF(I7<Inputs!$D$19,1,0) -> 1 | J17: =IF(J7<Inputs!$D$19,1,0) -> 1 | K17: =IF(K7<Inputs!$D$19,1,0) -> 1 | L17: =IF(L7<Inputs!$D$19,1,0) -> 1 | M17: =IF(M7<Inputs!$D$19,1,0) -> 1 | N17: =IF(N7<Inputs!$D$19,1,0) -> 1 | O17: =IF(O7<Inputs!$D$19,1,0) -> 1 | ... AQ17: =IF(AQ7<Inputs!$D$19,1,0) -> 0
B18: t.11 | C18: Operations phase | H18: =IF(AND(H7>=Inputs!$D$19,H7<Inputs!$D$19+Inputs!$D$21*2),1,0) -> 0 | I18: =IF(AND(I7>=Inputs!$D$19,I7<Inputs!$D$19+Inputs!$D$21*2),1,0) -> 0 | J18: =IF(AND(J7>=Inputs!$D$19,J7<Inputs!$D$19+Inputs!$D$21*2),1,0) -> 0 | K18: =IF(AND(K7>=Inputs!$D$19,K7<Inputs!$D$19+Inputs!$D$21*2),1,0) -> 0 | L18: =IF(AND(L7>=Inputs!$D$19,L7<Inputs!$D$19+Inputs!$D$21*2),1,0) -> 0 | M18: =IF(AND(M7>=Inputs!$D$19,M7<Inputs!$D$19+Inputs!$D$21*2),1,0) -> 0 | N18: =IF(AND(N7>=Inputs!$D$19,N7<Inputs!$D$19+Inputs!$D$21*2),1,0) -> 0 | O18: =IF(AND(O7>=Inputs!$D$19,O7<Inputs!$D$19+Inputs!$D$21*2),1,0) -> 0 | ... AQ18: =IF(AND(AQ7>=Inputs!$D$19,AQ7<Inputs!$D$19+Inputs!$D$21*2),1,0) -> 1
B19: t.12 | C19: Operating period index | H19: =IF(H18=1,H7-Inputs!$D$19+1,0) -> 0 | I19: =IF(I18=1,I7-Inputs!$D$19+1,0) -> 0 | J19: =IF(J18=1,J7-Inputs!$D$19+1,0) -> 0 | K19: =IF(K18=1,K7-Inputs!$D$19+1,0) -> 0 | L19: =IF(L18=1,L7-Inputs!$D$19+1,0) -> 0 | M19: =IF(M18=1,M7-Inputs!$D$19+1,0) -> 0 | N19: =IF(N18=1,N7-Inputs!$D$19+1,0) -> 0 | O19: =IF(O18=1,O7-Inputs!$D$19+1,0) -> 0 | ... AQ19: =IF(AQ18=1,AQ7-Inputs!$D$19+1,0) -> 24
B20: t.13 | C20: Operating year index | H20: =IF(H18=1,ROUNDUP(H19/2,0),0) -> 0 | I20: =IF(I18=1,ROUNDUP(I19/2,0),0) -> 0 | J20: =IF(J18=1,ROUNDUP(J19/2,0),0) -> 0 | K20: =IF(K18=1,ROUNDUP(K19/2,0),0) -> 0 | L20: =IF(L18=1,ROUNDUP(L19/2,0),0) -> 0 | M20: =IF(M18=1,ROUNDUP(M19/2,0),0) -> 0 | N20: =IF(N18=1,ROUNDUP(N19/2,0),0) -> 0 | O20: =IF(O18=1,ROUNDUP(O19/2,0),0) -> 0 | ... AQ20: =IF(AQ18=1,ROUNDUP(AQ19/2,0),0) -> 12
B21: t.14 | C21: Ramp-up period | H21: =IF(AND(H18=1,H20<=Inputs!$D$20),1,0) -> 0 | I21: =IF(AND(I18=1,I20<=Inputs!$D$20),1,0) -> 0 | J21: =IF(AND(J18=1,J20<=Inputs!$D$20),1,0) -> 0 | K21: =IF(AND(K18=1,K20<=Inputs!$D$20),1,0) -> 0 | L21: =IF(AND(L18=1,L20<=Inputs!$D$20),1,0) -> 0 | M21: =IF(AND(M18=1,M20<=Inputs!$D$20),1,0) -> 0 | N21: =IF(AND(N18=1,N20<=Inputs!$D$20),1,0) -> 0 | O21: =IF(AND(O18=1,O20<=Inputs!$D$20),1,0) -> 0 | ... AQ21: =IF(AND(AQ18=1,AQ20<=Inputs!$D$20),1,0) -> 0
B22: t.15 | C22: Steady-state period | H22: =IF(AND(H18=1,H20>Inputs!$D$20),1,0) -> 0 | I22: =IF(AND(I18=1,I20>Inputs!$D$20),1,0) -> 0 | J22: =IF(AND(J18=1,J20>Inputs!$D$20),1,0) -> 0 | K22: =IF(AND(K18=1,K20>Inputs!$D$20),1,0) -> 0 | L22: =IF(AND(L18=1,L20>Inputs!$D$20),1,0) -> 0 | M22: =IF(AND(M18=1,M20>Inputs!$D$20),1,0) -> 0 | N22: =IF(AND(N18=1,N20>Inputs!$D$20),1,0) -> 0 | O22: =IF(AND(O18=1,O20>Inputs!$D$20),1,0) -> 0 | ... AQ22: =IF(AND(AQ18=1,AQ20>Inputs!$D$20),1,0) -> 1
B24: FINANCING FLAGS (1 = active)
B25: t.20 | C25: Debt drawdown window | H25: =H17 -> 1 | I25: =I17 -> 1 | J25: =J17 -> 1 | K25: =K17 -> 1 | L25: =L17 -> 1 | M25: =M17 -> 1 | N25: =N17 -> 1 | O25: =O17 -> 1 | ... AQ25: =AQ17 -> 0
B26: t.21 | C26: Principal grace period (interest only) | H26: =IF(AND(H7>=3,H7<Inputs!$D$22),1,0) -> 0 | I26: =IF(AND(I7>=3,I7<Inputs!$D$22),1,0) -> 0 | J26: =IF(AND(J7>=3,J7<Inputs!$D$22),1,0) -> 1 | K26: =IF(AND(K7>=3,K7<Inputs!$D$22),1,0) -> 1 | L26: =IF(AND(L7>=3,L7<Inputs!$D$22),1,0) -> 1 | M26: =IF(AND(M7>=3,M7<Inputs!$D$22),1,0) -> 1 | N26: =IF(AND(N7>=3,N7<Inputs!$D$22),1,0) -> 1 | O26: =IF(AND(O7>=3,O7<Inputs!$D$22),1,0) -> 1 | ... AQ26: =IF(AND(AQ7>=3,AQ7<Inputs!$D$22),1,0) -> 0
B27: t.22 | C27: Senior principal repayment | H27: =IF(AND(H7>=Inputs!$D$22,H7<=Inputs!$D$22+Inputs!$D$23-1),1,0) -> 0 | I27: =IF(AND(I7>=Inputs!$D$22,I7<=Inputs!$D$22+Inputs!$D$23-1),1,0) -> 0 | J27: =IF(AND(J7>=Inputs!$D$22,J7<=Inputs!$D$22+Inputs!$D$23-1),1,0) -> 0 | K27: =IF(AND(K7>=Inputs!$D$22,K7<=Inputs!$D$22+Inputs!$D$23-1),1,0) -> 0 | L27: =IF(AND(L7>=Inputs!$D$22,L7<=Inputs!$D$22+Inputs!$D$23-1),1,0) -> 0 | M27: =IF(AND(M7>=Inputs!$D$22,M7<=Inputs!$D$22+Inputs!$D$23-1),1,0) -> 0 | N27: =IF(AND(N7>=Inputs!$D$22,N7<=Inputs!$D$22+Inputs!$D$23-1),1,0) -> 0 | O27: =IF(AND(O7>=Inputs!$D$22,O7<=Inputs!$D$22+Inputs!$D$23-1),1,0) -> 0 | ... AQ27: =IF(AND(AQ7>=Inputs!$D$22,AQ7<=Inputs!$D$22+Inputs!$D$23-1),1,0) -> 0
B28: t.23 | C28: Repayment instalment number | H28: =IF(H27=1,H7-Inputs!$D$22+1,0) -> 0 | I28: =IF(I27=1,I7-Inputs!$D$22+1,0) -> 0 | J28: =IF(J27=1,J7-Inputs!$D$22+1,0) -> 0 | K28: =IF(K27=1,K7-Inputs!$D$22+1,0) -> 0 | L28: =IF(L27=1,L7-Inputs!$D$22+1,0) -> 0 | M28: =IF(M27=1,M7-Inputs!$D$22+1,0) -> 0 | N28: =IF(N27=1,N7-Inputs!$D$22+1,0) -> 0 | O28: =IF(O27=1,O7-Inputs!$D$22+1,0) -> 0 | ... AQ28: =IF(AQ27=1,AQ7-Inputs!$D$22+1,0) -> 0
B29: t.24 | C29: DSRA required | H29: =IF(AND(H7>=Inputs!$D$22-1,H7<=Inputs!$D$22+Inputs!$D$23-2),1,0) -> 0 | I29: =IF(AND(I7>=Inputs!$D$22-1,I7<=Inputs!$D$22+Inputs!$D$23-2),1,0) -> 0 | J29: =IF(AND(J7>=Inputs!$D$22-1,J7<=Inputs!$D$22+Inputs!$D$23-2),1,0) -> 0 | K29: =IF(AND(K7>=Inputs!$D$22-1,K7<=Inputs!$D$22+Inputs!$D$23-2),1,0) -> 0 | L29: =IF(AND(L7>=Inputs!$D$22-1,L7<=Inputs!$D$22+Inputs!$D$23-2),1,0) -> 0 | M29: =IF(AND(M7>=Inputs!$D$22-1,M7<=Inputs!$D$22+Inputs!$D$23-2),1,0) -> 0 | N29: =IF(AND(N7>=Inputs!$D$22-1,N7<=Inputs!$D$22+Inputs!$D$23-2),1,0) -> 0 | O29: =IF(AND(O7>=Inputs!$D$22-1,O7<=Inputs!$D$22+Inputs!$D$23-2),1,0) -> 0 | ... AQ29: =IF(AND(AQ7>=Inputs!$D$22-1,AQ7<=Inputs!$D$22+Inputs!$D$23-2),1,0) -> 0
B30: t.25 | C30: Vitol prepayment facility outstanding | H30: =IF(AND(H7>=12,H7<=13),1,0) -> 0 | I30: =IF(AND(I7>=12,I7<=13),1,0) -> 0 | J30: =IF(AND(J7>=12,J7<=13),1,0) -> 0 | K30: =IF(AND(K7>=12,K7<=13),1,0) -> 0 | L30: =IF(AND(L7>=12,L7<=13),1,0) -> 0 | M30: =IF(AND(M7>=12,M7<=13),1,0) -> 0 | N30: =IF(AND(N7>=12,N7<=13),1,0) -> 0 | O30: =IF(AND(O7>=12,O7<=13),1,0) -> 0 | ... AQ30: =IF(AND(AQ7>=12,AQ7<=13),1,0) -> 0
B32: ROUTE AVAILABILITY FLAGS (1 = route open)
B33: t.30 | C33: Indorama route available | H33: =H18 -> 0 | I33: =I18 -> 0 | J33: =J18 -> 0 | K33: =K18 -> 0 | L33: =L18 -> 0 | M33: =M18 -> 0 | N33: =N18 -> 0 | O33: =O18 -> 0 | ... AQ33: =AQ18 -> 1
B34: t.31 | C34: NLNG route available | H34: =IF(AND(H18=1,H7>=Inputs!$D$41),1,0) -> 0 | I34: =IF(AND(I18=1,I7>=Inputs!$D$41),1,0) -> 0 | J34: =IF(AND(J18=1,J7>=Inputs!$D$41),1,0) -> 0 | K34: =IF(AND(K18=1,K7>=Inputs!$D$41),1,0) -> 0 | L34: =IF(AND(L18=1,L7>=Inputs!$D$41),1,0) -> 0 | M34: =IF(AND(M18=1,M7>=Inputs!$D$41),1,0) -> 0 | N34: =IF(AND(N18=1,N7>=Inputs!$D$41),1,0) -> 0 | O34: =IF(AND(O18=1,O7>=Inputs!$D$41),1,0) -> 0 | ... AQ34: =IF(AND(AQ18=1,AQ7>=Inputs!$D$41),1,0) -> 1
B35: t.32 | C35: OB3 domestic route available | H35: =IF(AND(H18=1,H7>=Inputs!$D$42),1,0) -> 0 | I35: =IF(AND(I18=1,I7>=Inputs!$D$42),1,0) -> 0 | J35: =IF(AND(J18=1,J7>=Inputs!$D$42),1,0) -> 0 | K35: =IF(AND(K18=1,K7>=Inputs!$D$42),1,0) -> 0 | L35: =IF(AND(L18=1,L7>=Inputs!$D$42),1,0) -> 0 | M35: =IF(AND(M18=1,M7>=Inputs!$D$42),1,0) -> 0 | N35: =IF(AND(N18=1,N7>=Inputs!$D$42),1,0) -> 0 | O35: =IF(AND(O18=1,O7>=Inputs!$D$42),1,0) -> 0 | ... AQ35: =IF(AND(AQ18=1,AQ7>=Inputs!$D$42),1,0) -> 1
B37: CHECKS
C38: Periods built equals T.02 | D38: =IF(COUNT($H$7:$AQ$7)=Inputs!$D$16,"OK","CHECK") -> OK
C39: Construction and operations flags are mutually exclusive | D39: =IF(SUMPRODUCT($H$17:$AQ$17,$H$18:$AQ$18)=0,"OK","CHECK") -> OK
C40: Final repayment instalment falls inside the model horizon | D40: =IF(Inputs!$D$22+Inputs!$D$23-1<=Inputs!$D$16,"OK","CHECK") -> OK

Sheet Construction & Funding
B2: CONSTRUCTION & FUNDING
B3: Sources and uses, time-phased drawdown, interest during construction, and the cost of the 2021-2026 completion delay. All figures in US$ million unless stated.
B6: A. SOURCES & USES OF FUNDS
C7: SOURCES | D7: Amount ($m) | E7: % of total | F7: Class
B8: s.01 | C8: Equity - Seplat Energy Plc (50%) | D8: =Inputs!$D$89+Inputs!$D$91 -> 230 | E8: =$D$8/$D$12 -> 0.30666667 | F8: Disclosed
B9: s.02 | C9: Equity - NGIC (50%) | D9: =Inputs!$D$90+Inputs!$D$92 -> 230 | E9: =$D$9/$D$12 -> 0.30666667 | F9: Disclosed
B10: s.03 | C10: Senior debt facility (closed Feb 2021) | D10: =Inputs!$D$73 -> 260 | E10: =$D$10/$D$12 -> 0.34666667 | F10: Disclosed
B11: s.04 | C11: Vitol prepayment facility (Q3 2025) | D11: =Inputs!$D$83 -> 30 | E11: =$D$11/$D$12 -> 0.04 | F11: Disclosed
C12: Total sources | D12: =SUM($D$8:$D$11) -> 750 | E12: =SUM($E$8:$E$11) -> 1
C14: USES
B15: u.01 | C15: EPC, process trains, LPG & condensate units | D15: 470 | E15: =$D$15/$D$22 -> 0.62666667 | F15: Estimated | H15: Two 150 MMscfd trains, LPG recovery, condensate stabilisation, 16 MW power plant
B16: u.02 | C16: Upstream tie-in, spur line & export pipeline works | D16: 45 | E16: =$D$16/$D$22 -> 0.06 | F16: Estimated | H16: Includes the 11 km Indorama gas export pipeline completed ahead of first gas
B17: u.03 | C17: Owner's costs, land, insurance & pre-operating | D17: 40 | E17: =$D$17/$D$22 -> 0.053333333 | F17: Estimated
B18: u.04 | C18: Delay-related costs 2022-2025 | D18: 35 | E18: =$D$18/$D$22 -> 0.046666667 | F18: Estimated | H18: Standby, remobilisation, re-commissioning and holding costs over the four-year slip
B19: u.05 | C19: Initial working capital & DSRA funding | D19: 25 | E19: =$D$19/$D$22 -> 0.033333333 | F19: Estimated
B20: u.06 | C20: Capitalised interest & fees during construction | D20: =$D$47 -> 118.07751 | E20: =$D$20/$D$22 -> 0.15743668 | F20: Derived
B21: u.07 | C21: Contingency & other project costs (balancing figure) | D21: =$D$12-SUM($D$15:$D$20) -> 16.922493 | E21: =$D$21/$D$22 -> 0.022563324 | F21: Derived | H21: Balances total uses to total sources; the individual use lines above are estimates, so this line absorbs the estimation error
C22: Total uses | D22: =SUM($D$15:$D$21) -> 750 | E22: =SUM($E$15:$E$21) -> 1
B24: B. FUNDING DRAWDOWN PROFILE
D25: Commitment | E25: Profile sum | H25: =Timeline!H$10 -> H1 2020 | I25: =Timeline!I$10 -> H2 2020 | J25: =Timeline!J$10 -> H1 2021 | K25: =Timeline!K$10 -> H2 2021 | L25: =Timeline!L$10 -> H1 2022 | M25: =Timeline!M$10 -> H2 2022 | N25: =Timeline!N$10 -> H1 2023 | O25: =Timeline!O$10 -> H2 2023 | ... AQ25: =Timeline!AQ$10 -> H2 2037
B26: b.01 | C26: Original equity (combined) - drawdown % | D26: =Inputs!$D$89+Inputs!$D$90 -> 420 | E26: =SUM($H26:$AQ26) -> 1 | H26: 0.3 | I26: 0.2 | J26: 0.15 | K26: 0.12 | L26: 0.08 | M26: 0.06 | N26: 0.04 | O26: 0.03 | P26: 0.02 | Q26: 0 | R26: 0 | S26: 0 | T26: 0 | U26: 0 | V26: 0 | W26: 0 | X26: 0 | Y26: 0 | Z26: 0 | AA26: 0 | AB26: 0 | AC26: 0 | AD26: 0 | AE26: 0 | AF26: 0 | AG26: 0 | AH26: 0 | AI26: 0 | AJ26: 0 | AK26: 0 | AL26: 0 | AM26: 0 | AN26: 0 | AO26: 0 | AP26: 0 | AQ26: 0
B27: b.02 | C27: Additional 2025 equity (combined) - drawdown % | D27: =Inputs!$D$91+Inputs!$D$92 -> 40 | E27: =SUM($H27:$AQ27) -> 1 | H27: 0 | I27: 0 | J27: 0 | K27: 0 | L27: 0 | M27: 0 | N27: 0 | O27: 0 | P27: 0 | Q27: 0 | R27: 1 | S27: 0 | T27: 0 | U27: 0 | V27: 0 | W27: 0 | X27: 0 | Y27: 0 | Z27: 0 | AA27: 0 | AB27: 0 | AC27: 0 | AD27: 0 | AE27: 0 | AF27: 0 | AG27: 0 | AH27: 0 | AI27: 0 | AJ27: 0 | AK27: 0 | AL27: 0 | AM27: 0 | AN27: 0 | AO27: 0 | AP27: 0 | AQ27: 0
B28: b.03 | C28: Senior debt facility - drawdown % | D28: =Inputs!$D$73 -> 260 | E28: =SUM($H28:$AQ28) -> 1 | H28: 0 | I28: 0 | J28: 0.3 | K28: 0.25 | L28: 0.2 | M28: 0.15 | N28: 0.1 | O28: 0 | P28: 0 | Q28: 0 | R28: 0 | S28: 0 | T28: 0 | U28: 0 | V28: 0 | W28: 0 | X28: 0 | Y28: 0 | Z28: 0 | AA28: 0 | AB28: 0 | AC28: 0 | AD28: 0 | AE28: 0 | AF28: 0 | AG28: 0 | AH28: 0 | AI28: 0 | AJ28: 0 | AK28: 0 | AL28: 0 | AM28: 0 | AN28: 0 | AO28: 0 | AP28: 0 | AQ28: 0
B29: b.04 | C29: Vitol prepayment facility - drawdown % | D29: =Inputs!$D$83 -> 30 | E29: =SUM($H29:$AQ29) -> 1 | H29: 0 | I29: 0 | J29: 0 | K29: 0 | L29: 0 | M29: 0 | N29: 0 | O29: 0 | P29: 0 | Q29: 0 | R29: 0 | S29: 1 | T29: 0 | U29: 0 | V29: 0 | W29: 0 | X29: 0 | Y29: 0 | Z29: 0 | AA29: 0 | AB29: 0 | AC29: 0 | AD29: 0 | AE29: 0 | AF29: 0 | AG29: 0 | AH29: 0 | AI29: 0 | AJ29: 0 | AK29: 0 | AL29: 0 | AM29: 0 | AN29: 0 | AO29: 0 | AP29: 0 | AQ29: 0
B31: b.10 | C31: Equity drawn - Seplat Energy | D31: =SUM($H31:$AQ31) -> 230 | H31: =H26*Inputs!$D$89+H27*Inputs!$D$91 -> 63 | I31: =I26*Inputs!$D$89+I27*Inputs!$D$91 -> 42 | J31: =J26*Inputs!$D$89+J27*Inputs!$D$91 -> 31.5 | K31: =K26*Inputs!$D$89+K27*Inputs!$D$91 -> 25.2 | L31: =L26*Inputs!$D$89+L27*Inputs!$D$91 -> 16.8 | M31: =M26*Inputs!$D$89+M27*Inputs!$D$91 -> 12.6 | N31: =N26*Inputs!$D$89+N27*Inputs!$D$91 -> 8.4 | O31: =O26*Inputs!$D$89+O27*Inputs!$D$91 -> 6.3 | ... AQ31: =AQ26*Inputs!$D$89+AQ27*Inputs!$D$91 -> 0
B32: b.11 | C32: Equity drawn - NGIC | D32: =SUM($H32:$AQ32) -> 230 | H32: =H26*Inputs!$D$90+H27*Inputs!$D$92 -> 63 | I32: =I26*Inputs!$D$90+I27*Inputs!$D$92 -> 42 | J32: =J26*Inputs!$D$90+J27*Inputs!$D$92 -> 31.5 | K32: =K26*Inputs!$D$90+K27*Inputs!$D$92 -> 25.2 | L32: =L26*Inputs!$D$90+L27*Inputs!$D$92 -> 16.8 | M32: =M26*Inputs!$D$90+M27*Inputs!$D$92 -> 12.6 | N32: =N26*Inputs!$D$90+N27*Inputs!$D$92 -> 8.4 | O32: =O26*Inputs!$D$90+O27*Inputs!$D$92 -> 6.3 | ... AQ32: =AQ26*Inputs!$D$90+AQ27*Inputs!$D$92 -> 0
B33: b.12 | C33: Senior debt drawn | D33: =SUM($H33:$AQ33) -> 260 | H33: =H28*Inputs!$D$73 -> 0 | I33: =I28*Inputs!$D$73 -> 0 | J33: =J28*Inputs!$D$73 -> 78 | K33: =K28*Inputs!$D$73 -> 65 | L33: =L28*Inputs!$D$73 -> 52 | M33: =M28*Inputs!$D$73 -> 39 | N33: =N28*Inputs!$D$73 -> 26 | O33: =O28*Inputs!$D$73 -> 0 | ... AQ33: =AQ28*Inputs!$D$73 -> 0
B34: b.13 | C34: Vitol prepayment facility drawn | D34: =SUM($H34:$AQ34) -> 30 | H34: =H29*Inputs!$D$83 -> 0 | I34: =I29*Inputs!$D$83 -> 0 | J34: =J29*Inputs!$D$83 -> 0 | K34: =K29*Inputs!$D$83 -> 0 | L34: =L29*Inputs!$D$83 -> 0 | M34: =M29*Inputs!$D$83 -> 0 | N34: =N29*Inputs!$D$83 -> 0 | O34: =O29*Inputs!$D$83 -> 0 | ... AQ34: =AQ29*Inputs!$D$83 -> 0
B35: b.14 | C35: Total funding drawn in period | D35: =SUM($H35:$AQ35) -> 750 | H35: =SUM(H31:H34) -> 126 | I35: =SUM(I31:I34) -> 84 | J35: =SUM(J31:J34) -> 141 | K35: =SUM(K31:K34) -> 115.4 | L35: =SUM(L31:L34) -> 85.6 | M35: =SUM(M31:M34) -> 64.2 | N35: =SUM(N31:N34) -> 42.8 | O35: =SUM(O31:O34) -> 12.6 | ... AQ35: =SUM(AQ31:AQ34) -> 0
B36: b.15 | C36: Cumulative funding drawn | H36: =H35 -> 126 | I36: =H36+I35 -> 210 | J36: =I36+J35 -> 351 | K36: =J36+K35 -> 466.4 | L36: =K36+L35 -> 552 | M36: =L36+M35 -> 616.2 | N36: =M36+N35 -> 659 | O36: =N36+O35 -> 671.6 | P36: =O36+P35 -> 680 | ... AQ36: =AP36+AQ35 -> 750
B38: C. INTEREST DURING CONSTRUCTION
D39: Total | H39: =Timeline!H$10 -> H1 2020 | I39: =Timeline!I$10 -> H2 2020 | J39: =Timeline!J$10 -> H1 2021 | K39: =Timeline!K$10 -> H2 2021 | L39: =Timeline!L$10 -> H1 2022 | M39: =Timeline!M$10 -> H2 2022 | N39: =Timeline!N$10 -> H1 2023 | O39: =Timeline!O$10 -> H2 2023 | ... AQ39: =Timeline!AQ$10 -> H2 2037
B40: c.01 | C40: Senior debt - opening balance | H40: =0 -> 0 | I40: =H42 -> 0 | J40: =I42 -> 0 | K40: =J42 -> 78 | L40: =K42 -> 143 | M40: =L42 -> 195 | N40: =M42 -> 234 | O40: =N42 -> 260 | P40: =O42 -> 260 | ... AQ40: =AP42 -> 260
B41: c.02 | C41: Senior debt drawn in period | H41: =H33 -> 0 | I41: =I33 -> 0 | J41: =J33 -> 78 | K41: =K33 -> 65 | L41: =L33 -> 52 | M41: =M33 -> 39 | N41: =N33 -> 26 | O41: =O33 -> 0 | ... AQ41: =AQ33 -> 0
B42: c.03 | C42: Senior debt - closing balance (pre-amortisation) | H42: =H40+H41 -> 0 | I42: =I40+I41 -> 0 | J42: =J40+J41 -> 78 | K42: =K40+K41 -> 143 | L42: =L40+L41 -> 195 | M42: =M40+M41 -> 234 | N42: =N40+N41 -> 260 | O42: =O40+O41 -> 260 | ... AQ42: =AQ40+AQ41 -> 260
B43: c.04 | C43: Senior interest accrued in period | D43: =SUM($H43:$AQ43) -> 104.12466 | H43: =IF(Timeline!H$17=1,(H40+H42)/2*Inputs!$D$76*Timeline!H$14,0) -> 0 | I43: =IF(Timeline!I$17=1,(I40+I42)/2*Inputs!$D$76*Timeline!I$14,0) -> 0 | J43: =IF(Timeline!J$17=1,(J40+J42)/2*Inputs!$D$76*Timeline!J$14,0) -> 1.9339726 | K43: =IF(Timeline!K$17=1,(K40+K42)/2*Inputs!$D$76*Timeline!K$14,0) -> 5.570411 | L43: =IF(Timeline!L$17=1,(L40+L42)/2*Inputs!$D$76*Timeline!L$14,0) -> 8.3805479 | M43: =IF(Timeline!M$17=1,(M40+M42)/2*Inputs!$D$76*Timeline!M$14,0) -> 10.813151 | N43: =IF(Timeline!N$17=1,(N40+N42)/2*Inputs!$D$76*Timeline!N$14,0) -> 12.248493 | O43: =IF(Timeline!O$17=1,(O40+O42)/2*Inputs!$D$76*Timeline!O$14,0) -> 13.106849 | ... AQ43: =IF(Timeline!AQ$17=1,(AQ40+AQ42)/2*Inputs!$D$76*Timeline!AQ$14,0) -> 0
B44: c.05 | C44: Commitment fee on undrawn senior | D44: =SUM($H44:$AQ44) -> 4.5528493 | H44: =IF(Timeline!H$17=1,MAX(0,Inputs!$D$73-H42)*Inputs!$D$78*Timeline!H$14,0) -> 1.2964384 | I44: =IF(Timeline!I$17=1,MAX(0,Inputs!$D$73-I42)*Inputs!$D$78*Timeline!I$14,0) -> 1.3106849 | J44: =IF(Timeline!J$17=1,MAX(0,Inputs!$D$73-J42)*Inputs!$D$78*Timeline!J$14,0) -> 0.90252055 | K44: =IF(Timeline!K$17=1,MAX(0,Inputs!$D$73-K42)*Inputs!$D$78*Timeline!K$14,0) -> 0.58980822 | L44: =IF(Timeline!L$17=1,MAX(0,Inputs!$D$73-L42)*Inputs!$D$78*Timeline!L$14,0) -> 0.32232877 | M44: =IF(Timeline!M$17=1,MAX(0,Inputs!$D$73-M42)*Inputs!$D$78*Timeline!M$14,0) -> 0.13106849 | N44: =IF(Timeline!N$17=1,MAX(0,Inputs!$D$73-N42)*Inputs!$D$78*Timeline!N$14,0) -> 0 | O44: =IF(Timeline!O$17=1,MAX(0,Inputs!$D$73-O42)*Inputs!$D$78*Timeline!O$14,0) -> 0 | ... AQ44: =IF(Timeline!AQ$17=1,MAX(0,Inputs!$D$73-AQ42)*Inputs!$D$78*Timeline!AQ$14,0) -> 0
B45: c.06 | C45: Upfront arrangement fee | D45: =SUM($H45:$AQ45) -> 5.2 | H45: =H33*Inputs!$D$77 -> 0 | I45: =I33*Inputs!$D$77 -> 0 | J45: =J33*Inputs!$D$77 -> 1.56 | K45: =K33*Inputs!$D$77 -> 1.3 | L45: =L33*Inputs!$D$77 -> 1.04 | M45: =M33*Inputs!$D$77 -> 0.78 | N45: =N33*Inputs!$D$77 -> 0.52 | O45: =O33*Inputs!$D$77 -> 0 | ... AQ45: =AQ33*Inputs!$D$77 -> 0
B46: c.07 | C46: Vitol prepayment facility interest | D46: =SUM($H46:$AQ46) -> 4.2 | H46: =Timeline!H$30*Inputs!$D$83*Inputs!$D$85*Timeline!H$14 -> 0 | I46: =Timeline!I$30*Inputs!$D$83*Inputs!$D$85*Timeline!I$14 -> 0 | J46: =Timeline!J$30*Inputs!$D$83*Inputs!$D$85*Timeline!J$14 -> 0 | K46: =Timeline!K$30*Inputs!$D$83*Inputs!$D$85*Timeline!K$14 -> 0 | L46: =Timeline!L$30*Inputs!$D$83*Inputs!$D$85*Timeline!L$14 -> 0 | M46: =Timeline!M$30*Inputs!$D$83*Inputs!$D$85*Timeline!M$14 -> 0 | N46: =Timeline!N$30*Inputs!$D$83*Inputs!$D$85*Timeline!N$14 -> 0 | O46: =Timeline!O$30*Inputs!$D$83*Inputs!$D$85*Timeline!O$14 -> 0 | ... AQ46: =Timeline!AQ$30*Inputs!$D$83*Inputs!$D$85*Timeline!AQ$14 -> 0
B47: c.08 | C47: Total financing cost capitalised in period | D47: =SUM($H47:$AQ47) -> 118.07751 | H47: =H43+H44+H45+H46 -> 1.2964384 | I47: =I43+I44+I45+I46 -> 1.3106849 | J47: =J43+J44+J45+J46 -> 4.3964932 | K47: =K43+K44+K45+K46 -> 7.4602192 | L47: =L43+L44+L45+L46 -> 9.7428767 | M47: =M43+M44+M45+M46 -> 11.724219 | N47: =N43+N44+N45+N46 -> 12.768493 | O47: =O43+O44+O45+O46 -> 13.106849 | ... AQ47: =AQ43+AQ44+AQ45+AQ46 -> 0
...

Sheet Throughput
B2: THROUGHPUT & OFFTAKE
B3: Deliverable volume is the lesser of plant-driven supply and the capacity of the routes that are actually open. Volume is then allocated across routes in contractual priority.
B6: A. PLANT SUPPLY
D7: Total | E7: Unit | H7: =Timeline!H$10 -> H1 2020 | I7: =Timeline!I$10 -> H2 2020 | J7: =Timeline!J$10 -> H1 2021 | K7: =Timeline!K$10 -> H2 2021 | L7: =Timeline!L$10 -> H1 2022 | M7: =Timeline!M$10 -> H2 2022 | N7: =Timeline!N$10 -> H1 2023 | O7: =Timeline!O$10 -> H2 2023 | ... AQ7: =Timeline!AQ$10 -> H2 2037
B8: g.01 | C8: Utilisation of design capacity | D8: =MAX($H8:$AQ8) -> 0.85 | E8: % | H8: =IF(Timeline!H$20=0,0,IF(Timeline!H$20=1,Inputs!$D$30,IF(Timeline!H$20=2,Inputs!$D$31,IF(Timeline!H$20=3,Inputs!$D$32,IF(Timeline!H$20=4,Inputs!$D$33,Inputs!$D$34))))) -> 0 | I8: =IF(Timeline!I$20=0,0,IF(Timeline!I$20=1,Inputs!$D$30,IF(Timeline!I$20=2,Inputs!$D$31,IF(Timeline!I$20=3,Inputs!$D$32,IF(Timeline!I$20=4,Inputs!$D$33,Inputs!$D$34))))) -> 0 | J8: =IF(Timeline!J$20=0,0,IF(Timeline!J$20=1,Inputs!$D$30,IF(Timeline!J$20=2,Inputs!$D$31,IF(Timeline!J$20=3,Inputs!$D$32,IF(Timeline!J$20=4,Inputs!$D$33,Inputs!$D$34))))) -> 0 | K8: =IF(Timeline!K$20=0,0,IF(Timeline!K$20=1,Inputs!$D$30,IF(Timeline!K$20=2,Inputs!$D$31,IF(Timeline!K$20=3,Inputs!$D$32,IF(Timeline!K$20=4,Inputs!$D$33,Inputs!$D$34))))) -> 0 | L8: =IF(Timeline!L$20=0,0,IF(Timeline!L$20=1,Inputs!$D$30,IF(Timeline!L$20=2,Inputs!$D$31,IF(Timeline!L$20=3,Inputs!$D$32,IF(Timeline!L$20=4,Inputs!$D$33,Inputs!$D$34))))) -> 0 | M8: =IF(Timeline!M$20=0,0,IF(Timeline!M$20=1,Inputs!$D$30,IF(Timeline!M$20=2,Inputs!$D$31,IF(Timeline!M$20=3,Inputs!$D$32,IF(Timeline!M$20=4,Inputs!$D$33,Inputs!$D$34))))) -> 0 | N8: =IF(Timeline!N$20=0,0,IF(Timeline!N$20=1,Inputs!$D$30,IF(Timeline!N$20=2,Inputs!$D$31,IF(Timeline!N$20=3,Inputs!$D$32,IF(Timeline!N$20=4,Inputs!$D$33,Inputs!$D$34))))) -> 0 | O8: =IF(Timeline!O$20=0,0,IF(Timeline!O$20=1,Inputs!$D$30,IF(Timeline!O$20=2,Inputs!$D$31,IF(Timeline!O$20=3,Inputs!$D$32,IF(Timeline!O$20=4,Inputs!$D$33,Inputs!$D$34))))) -> 0 | ... AQ8: =IF(Timeline!AQ$20=0,0,IF(Timeline!AQ$20=1,Inputs!$D$30,IF(Timeline!AQ$20=2,Inputs!$D$31,IF(Timeline!AQ$20=3,Inputs!$D$32,IF(Timeline!AQ$20=4,Inputs!$D$33,Inputs!$D$34))))) -> 0.85
B9: g.02 | C9: Plant availability | E9: % | H9: =Timeline!H$18*Inputs!$D$27 -> 0 | I9: =Timeline!I$18*Inputs!$D$27 -> 0 | J9: =Timeline!J$18*Inputs!$D$27 -> 0 | K9: =Timeline!K$18*Inputs!$D$27 -> 0 | L9: =Timeline!L$18*Inputs!$D$27 -> 0 | M9: =Timeline!M$18*Inputs!$D$27 -> 0 | N9: =Timeline!N$18*Inputs!$D$27 -> 0 | O9: =Timeline!O$18*Inputs!$D$27 -> 0 | ... AQ9: =Timeline!AQ$18*Inputs!$D$27 -> 0.92
B10: g.03 | C10: Plant-driven supply capability | D10: =MAX($H10:$AQ10) -> 234.6 | E10: MMscfd | H10: =Inputs!$D$26*H8*H9 -> 0 | I10: =Inputs!$D$26*I8*I9 -> 0 | J10: =Inputs!$D$26*J8*J9 -> 0 | K10: =Inputs!$D$26*K8*K9 -> 0 | L10: =Inputs!$D$26*L8*L9 -> 0 | M10: =Inputs!$D$26*M8*M9 -> 0 | N10: =Inputs!$D$26*N8*N9 -> 0 | O10: =Inputs!$D$26*O8*O9 -> 0 | ... AQ10: =Inputs!$D$26*AQ8*AQ9 -> 234.6
B12: B. ROUTE CAPACITY AVAILABLE
B13: g.10 | C13: Indorama - firm | D13: =MAX($H13:$AQ13) -> 60 | E13: MMscfd | H13: =Inputs!$D$37*Timeline!H$33 -> 0 | I13: =Inputs!$D$37*Timeline!I$33 -> 0 | J13: =Inputs!$D$37*Timeline!J$33 -> 0 | K13: =Inputs!$D$37*Timeline!K$33 -> 0 | L13: =Inputs!$D$37*Timeline!L$33 -> 0 | M13: =Inputs!$D$37*Timeline!M$33 -> 0 | N13: =Inputs!$D$37*Timeline!N$33 -> 0 | O13: =Inputs!$D$37*Timeline!O$33 -> 0 | ... AQ13: =Inputs!$D$37*Timeline!AQ$33 -> 60
B14: g.11 | C14: Indorama - interruptible | D14: =MAX($H14:$AQ14) -> 14 | E14: MMscfd | H14: =Inputs!$D$38*Timeline!H$33*Inputs!$D$43 -> 0 | I14: =Inputs!$D$38*Timeline!I$33*Inputs!$D$43 -> 0 | J14: =Inputs!$D$38*Timeline!J$33*Inputs!$D$43 -> 0 | K14: =Inputs!$D$38*Timeline!K$33*Inputs!$D$43 -> 0 | L14: =Inputs!$D$38*Timeline!L$33*Inputs!$D$43 -> 0 | M14: =Inputs!$D$38*Timeline!M$33*Inputs!$D$43 -> 0 | N14: =Inputs!$D$38*Timeline!N$33*Inputs!$D$43 -> 0 | O14: =Inputs!$D$38*Timeline!O$33*Inputs!$D$43 -> 0 | ... AQ14: =Inputs!$D$38*Timeline!AQ$33*Inputs!$D$43 -> 14
B15: g.12 | C15: NLNG - interruptible | D15: =MAX($H15:$AQ15) -> 56 | E15: MMscfd | H15: =Inputs!$D$39*Timeline!H$34*Inputs!$D$43 -> 0 | I15: =Inputs!$D$39*Timeline!I$34*Inputs!$D$43 -> 0 | J15: =Inputs!$D$39*Timeline!J$34*Inputs!$D$43 -> 0 | K15: =Inputs!$D$39*Timeline!K$34*Inputs!$D$43 -> 0 | L15: =Inputs!$D$39*Timeline!L$34*Inputs!$D$43 -> 0 | M15: =Inputs!$D$39*Timeline!M$34*Inputs!$D$43 -> 0 | N15: =Inputs!$D$39*Timeline!N$34*Inputs!$D$43 -> 0 | O15: =Inputs!$D$39*Timeline!O$34*Inputs!$D$43 -> 0 | ... AQ15: =Inputs!$D$39*Timeline!AQ$34*Inputs!$D$43 -> 56
B16: g.13 | C16: OB3 - domestic | D16: =MAX($H16:$AQ16) -> 140 | E16: MMscfd | H16: =Inputs!$D$40*Timeline!H$35 -> 0 | I16: =Inputs!$D$40*Timeline!I$35 -> 0 | J16: =Inputs!$D$40*Timeline!J$35 -> 0 | K16: =Inputs!$D$40*Timeline!K$35 -> 0 | L16: =Inputs!$D$40*Timeline!L$35 -> 0 | M16: =Inputs!$D$40*Timeline!M$35 -> 0 | N16: =Inputs!$D$40*Timeline!N$35 -> 0 | O16: =Inputs!$D$40*Timeline!O$35 -> 0 | ... AQ16: =Inputs!$D$40*Timeline!AQ$35 -> 140
B17: g.14 | C17: Total route capacity available | D17: =MAX($H17:$AQ17) -> 270 | E17: MMscfd | H17: =SUM(H13:H16) -> 0 | I17: =SUM(I13:I16) -> 0 | J17: =SUM(J13:J16) -> 0 | K17: =SUM(K13:K16) -> 0 | L17: =SUM(L13:L16) -> 0 | M17: =SUM(M13:M16) -> 0 | N17: =SUM(N13:N16) -> 0 | O17: =SUM(O13:O16) -> 0 | ... AQ17: =SUM(AQ13:AQ16) -> 270
B19: C. DELIVERED VOLUME & ROUTE ALLOCATION
B20: g.20 | C20: Processed gas delivered | D20: =MAX($H20:$AQ20) -> 234.6 | E20: MMscfd | H20: =MIN(H10,H17) -> 0 | I20: =MIN(I10,I17) -> 0 | J20: =MIN(J10,J17) -> 0 | K20: =MIN(K10,K17) -> 0 | L20: =MIN(L10,L17) -> 0 | M20: =MIN(M10,M17) -> 0 | N20: =MIN(N10,N17) -> 0 | O20: =MIN(O10,O17) -> 0 | ... AQ20: =MIN(AQ10,AQ17) -> 234.6
B21: g.21 | C21: Allocated to Indorama firm | D21: =MAX($H21:$AQ21) -> 60 | E21: MMscfd | H21: =MIN(H20,H13) -> 0 | I21: =MIN(I20,I13) -> 0 | J21: =MIN(J20,J13) -> 0 | K21: =MIN(K20,K13) -> 0 | L21: =MIN(L20,L13) -> 0 | M21: =MIN(M20,M13) -> 0 | N21: =MIN(N20,N13) -> 0 | O21: =MIN(O20,O13) -> 0 | ... AQ21: =MIN(AQ20,AQ13) -> 60
B22: g.22 | C22: Allocated to Indorama interruptible | D22: =MAX($H22:$AQ22) -> 14 | E22: MMscfd | H22: =MIN(MAX(0,H20-H21),H14) -> 0 | I22: =MIN(MAX(0,I20-I21),I14) -> 0 | J22: =MIN(MAX(0,J20-J21),J14) -> 0 | K22: =MIN(MAX(0,K20-K21),K14) -> 0 | L22: =MIN(MAX(0,L20-L21),L14) -> 0 | M22: =MIN(MAX(0,M20-M21),M14) -> 0 | N22: =MIN(MAX(0,N20-N21),N14) -> 0 | O22: =MIN(MAX(0,O20-O21),O14) -> 0 | ... AQ22: =MIN(MAX(0,AQ20-AQ21),AQ14) -> 14
B23: g.23 | C23: Allocated to NLNG | D23: =MAX($H23:$AQ23) -> 56 | E23: MMscfd | H23: =MIN(MAX(0,H20-H21-H22),H15) -> 0 | I23: =MIN(MAX(0,I20-I21-I22),I15) -> 0 | J23: =MIN(MAX(0,J20-J21-J22),J15) -> 0 | K23: =MIN(MAX(0,K20-K21-K22),K15) -> 0 | L23: =MIN(MAX(0,L20-L21-L22),L15) -> 0 | M23: =MIN(MAX(0,M20-M21-M22),M15) -> 0 | N23: =MIN(MAX(0,N20-N21-N22),N15) -> 0 | O23: =MIN(MAX(0,O20-O21-O22),O15) -> 0 | ... AQ23: =MIN(MAX(0,AQ20-AQ21-AQ22),AQ15) -> 56
B24: g.24 | C24: Allocated to OB3 domestic | D24: =MAX($H24:$AQ24) -> 104.6 | E24: MMscfd | H24: =MAX(0,H20-H21-H22-H23) -> 0 | I24: =MAX(0,I20-I21-I22-I23) -> 0 | J24: =MAX(0,J20-J21-J22-J23) -> 0 | K24: =MAX(0,K20-K21-K22-K23) -> 0 | L24: =MAX(0,L20-L21-L22-L23) -> 0 | M24: =MAX(0,M20-M21-M22-M23) -> 0 | N24: =MAX(0,N20-N21-N22-N23) -> 0 | O24: =MAX(0,O20-O21-O22-O23) -> 0 | ... AQ24: =MAX(0,AQ20-AQ21-AQ22-AQ23) -> 104.6
B25: g.25 | C25: Domestic (naira-priced) volume | D25: =MAX($H25:$AQ25) -> 178.6 | E25: MMscfd | H25: =H21+H22+H24 -> 0 | I25: =I21+I22+I24 -> 0 | J25: =J21+J22+J24 -> 0 | K25: =K21+K22+K24 -> 0 | L25: =L21+L22+L24 -> 0 | M25: =M21+M22+M24 -> 0 | N25: =N21+N22+N24 -> 0 | O25: =O21+O22+O24 -> 0 | ... AQ25: =AQ21+AQ22+AQ24 -> 178.6
B26: g.26 | C26: Export (USD-priced) volume | D26: =MAX($H26:$AQ26) -> 56 | E26: MMscfd | H26: =H23 -> 0 | I26: =I23 -> 0 | J26: =J23 -> 0 | K26: =K23 -> 0 | L26: =L23 -> 0 | M26: =M23 -> 0 | N26: =N23 -> 0 | O26: =O23 -> 0 | ... AQ26: =AQ23 -> 56
B28: D. PERIOD VOLUMES & PRODUCT YIELDS
B29: g.30 | C29: Dry gas volume | D29: =SUM($H29:$AQ29) -> 869080.2 | E29: MMscf | H29: =H20*Timeline!H$13 -> 0 | I29: =I20*Timeline!I$13 -> 0 | J29: =J20*Timeline!J$13 -> 0 | K29: =K20*Timeline!K$13 -> 0 | L29: =L20*Timeline!L$13 -> 0 | M29: =M20*Timeline!M$13 -> 0 | N29: =N20*Timeline!N$13 -> 0 | O29: =O20*Timeline!O$13 -> 0 | ... AQ29: =AQ20*Timeline!AQ$13 -> 43166.4
B30: g.31 | C30: Dry gas volume - domestic | D30: =SUM($H30:$AQ30) -> 651226.2 | E30: MMscf | H30: =H25*Timeline!H$13 -> 0 | I30: =I25*Timeline!I$13 -> 0 | J30: =J25*Timeline!J$13 -> 0 | K30: =K25*Timeline!K$13 -> 0 | L30: =L25*Timeline!L$13 -> 0 | M30: =M25*Timeline!M$13 -> 0 | N30: =N25*Timeline!N$13 -> 0 | O30: =O25*Timeline!O$13 -> 0 | ... AQ30: =AQ25*Timeline!AQ$13 -> 32862.4
B31: g.32 | C31: Dry gas volume - export | D31: =SUM($H31:$AQ31) -> 217854 | E31: MMscf | H31: =H26*Timeline!H$13 -> 0 | I31: =I26*Timeline!I$13 -> 0 | J31: =J26*Timeline!J$13 -> 0 | K31: =K26*Timeline!K$13 -> 0 | L31: =L26*Timeline!L$13 -> 0 | M31: =M26*Timeline!M$13 -> 0 | N31: =N26*Timeline!N$13 -> 0 | O31: =O26*Timeline!O$13 -> 0 | ... AQ31: =AQ26*Timeline!AQ$13 -> 10304
B32: g.33 | C32: Wet gas feed volume | D32: =SUM($H32:$AQ32) -> 938606.62 | E32: MMscf | H32: =H29*Inputs!$D$53 -> 0 | I32: =I29*Inputs!$D$53 -> 0 | J32: =J29*Inputs!$D$53 -> 0 | K32: =K29*Inputs!$D$53 -> 0 | L32: =L29*Inputs!$D$53 -> 0 | M32: =M29*Inputs!$D$53 -> 0 | N32: =N29*Inputs!$D$53 -> 0 | O32: =O29*Inputs!$D$53 -> 0 | ... AQ32: =AQ29*Inputs!$D$53 -> 46619.712
B33: g.34 | C33: Condensate produced | D33: =SUM($H33:$AQ33) -> 41715.85 | E33: kbbl | H33: =H29*Inputs!$D$51/1000 -> 0 | I33: =I29*Inputs!$D$51/1000 -> 0 | J33: =J29*Inputs!$D$51/1000 -> 0 | K33: =K29*Inputs!$D$51/1000 -> 0 | L33: =L29*Inputs!$D$51/1000 -> 0 | M33: =M29*Inputs!$D$51/1000 -> 0 | N33: =N29*Inputs!$D$51/1000 -> 0 | O33: =O29*Inputs!$D$51/1000 -> 0 | ... AQ33: =AQ29*Inputs!$D$51/1000 -> 2071.9872
B34: g.35 | C34: LPG produced | D34: =SUM($H34:$AQ34) -> 6952.6416 | E34: kbbl | H34: =H29*Inputs!$D$52/1000 -> 0 | I34: =I29*Inputs!$D$52/1000 -> 0 | J34: =J29*Inputs!$D$52/1000 -> 0 | K34: =K29*Inputs!$D$52/1000 -> 0 | L34: =L29*Inputs!$D$52/1000 -> 0 | M34: =M29*Inputs!$D$52/1000 -> 0 | N34: =N29*Inputs!$D$52/1000 -> 0 | O34: =O29*Inputs!$D$52/1000 -> 0 | ... AQ34: =AQ29*Inputs!$D$52/1000 -> 345.3312
B35: g.36 | C35: Liquids rate (condensate + LPG) | D35: =MAX($H35:$AQ35) -> 13137.6 | E35: bopd | H35: =IF(Timeline!H$13=0,0,(H33+H34)*1000/Timeline!H$13) -> 0 | I35: =IF(Timeline!I$13=0,0,(I33+I34)*1000/Timeline!I$13) -> 0 | J35: =IF(Timeline!J$13=0,0,(J33+J34)*1000/Timeline!J$13) -> 0 | K35: =IF(Timeline!K$13=0,0,(K33+K34)*1000/Timeline!K$13) -> 0 | L35: =IF(Timeline!L$13=0,0,(L33+L34)*1000/Timeline!L$13) -> 0 | M35: =IF(Timeline!M$13=0,0,(M33+M34)*1000/Timeline!M$13) -> 0 | N35: =IF(Timeline!N$13=0,0,(N33+N34)*1000/Timeline!N$13) -> 0 | O35: =IF(Timeline!O$13=0,0,(O33+O34)*1000/Timeline!O$13) -> 0 | ... AQ35: =IF(Timeline!AQ$13=0,0,(AQ33+AQ34)*1000/Timeline!AQ$13) -> 13137.6
C37: Route allocation fills the Indorama firm contract first, then Indorama interruptible, then NLNG, then OB3. Interruptible routes are haircut by input O.07. Where the plant could supply more than the open routes can take, the excess is not produced - that constraint is the whole point of the OB3 scenario.
C38: Condensate yield of 48 bbl/MMscf is derived two ways and both agree: 2.0-2.5 kboepd of condensate at 40-52 MMscfd at start-up, and Seplat's OML 53 working-interest 2P ratio of 52.9 MMbbl liquids to 851.9 Bscf of gas. It is nonetheless the single largest swing factor in revenue and is stressed on the sensitivities tab.

Sheet Revenue
B2: PRICING & REVENUE
B3: Domestic gas is invoiced in naira. Where the naira price does not fully track devaluation (input M.08), the US dollar value of that revenue erodes. Liquids are dollar-priced.
B6: A. PRICE DECKS
D7: Total | E7: Unit | H7: =Timeline!H$10 -> H1 2020 | I7: =Timeline!I$10 -> H2 2020 | J7: =Timeline!J$10 -> H1 2021 | K7: =Timeline!K$10 -> H2 2021 | L7: =Timeline!L$10 -> H1 2022 | M7: =Timeline!M$10 -> H2 2022 | N7: =Timeline!N$10 -> H1 2023 | O7: =Timeline!O$10 -> H2 2023 | ... AQ7: =Timeline!AQ$10 -> H2 2037
B8: p.01 | C8: USD/NGN rate | E8: NGN/USD | H8: =Inputs!$D$97*(1+Inputs!$D$98)^MAX(0,Timeline!H$20-1) -> 1550 | I8: =Inputs!$D$97*(1+Inputs!$D$98)^MAX(0,Timeline!I$20-1) -> 1550 | J8: =Inputs!$D$97*(1+Inputs!$D$98)^MAX(0,Timeline!J$20-1) -> 1550 | K8: =Inputs!$D$97*(1+Inputs!$D$98)^MAX(0,Timeline!K$20-1) -> 1550 | L8: =Inputs!$D$97*(1+Inputs!$D$98)^MAX(0,Timeline!L$20-1) -> 1550 | M8: =Inputs!$D$97*(1+Inputs!$D$98)^MAX(0,Timeline!M$20-1) -> 1550 | N8: =Inputs!$D$97*(1+Inputs!$D$98)^MAX(0,Timeline!N$20-1) -> 1550 | O8: =Inputs!$D$97*(1+Inputs!$D$98)^MAX(0,Timeline!O$20-1) -> 1550 | ... AQ8: =Inputs!$D$97*(1+Inputs!$D$98)^MAX(0,Timeline!AQ$20-1) -> 3614.0404
B9: p.02 | C9: Naira gas price index | E9: x | H9: =(1+Inputs!$D$48+Inputs!$D$104*Inputs!$D$98)^MAX(0,Timeline!H$20-1) -> 1 | I9: =(1+Inputs!$D$48+Inputs!$D$104*Inputs!$D$98)^MAX(0,Timeline!I$20-1) -> 1 | J9: =(1+Inputs!$D$48+Inputs!$D$104*Inputs!$D$98)^MAX(0,Timeline!J$20-1) -> 1 | K9: =(1+Inputs!$D$48+Inputs!$D$104*Inputs!$D$98)^MAX(0,Timeline!K$20-1) -> 1 | L9: =(1+Inputs!$D$48+Inputs!$D$104*Inputs!$D$98)^MAX(0,Timeline!L$20-1) -> 1 | M9: =(1+Inputs!$D$48+Inputs!$D$104*Inputs!$D$98)^MAX(0,Timeline!M$20-1) -> 1 | N9: =(1+Inputs!$D$48+Inputs!$D$104*Inputs!$D$98)^MAX(0,Timeline!N$20-1) -> 1 | O9: =(1+Inputs!$D$48+Inputs!$D$104*Inputs!$D$98)^MAX(0,Timeline!O$20-1) -> 1 | ... AQ9: =(1+Inputs!$D$48+Inputs!$D$104*Inputs!$D$98)^MAX(0,Timeline!AQ$20-1) -> 1.95824
B10: p.03 | C10: Domestic gas price (USD equivalent) | E10: $/Mscf | H10: =Timeline!H$18*Inputs!$D$47*H9/((1+Inputs!$D$98)^MAX(0,Timeline!H$20-1)) -> 0 | I10: =Timeline!I$18*Inputs!$D$47*I9/((1+Inputs!$D$98)^MAX(0,Timeline!I$20-1)) -> 0 | J10: =Timeline!J$18*Inputs!$D$47*J9/((1+Inputs!$D$98)^MAX(0,Timeline!J$20-1)) -> 0 | K10: =Timeline!K$18*Inputs!$D$47*K9/((1+Inputs!$D$98)^MAX(0,Timeline!K$20-1)) -> 0 | L10: =Timeline!L$18*Inputs!$D$47*L9/((1+Inputs!$D$98)^MAX(0,Timeline!L$20-1)) -> 0 | M10: =Timeline!M$18*Inputs!$D$47*M9/((1+Inputs!$D$98)^MAX(0,Timeline!M$20-1)) -> 0 | N10: =Timeline!N$18*Inputs!$D$47*N9/((1+Inputs!$D$98)^MAX(0,Timeline!N$20-1)) -> 0 | O10: =Timeline!O$18*Inputs!$D$47*O9/((1+Inputs!$D$98)^MAX(0,Timeline!O$20-1)) -> 0 | ... AQ10: =Timeline!AQ$18*Inputs!$D$47*AQ9/((1+Inputs!$D$98)^MAX(0,Timeline!AQ$20-1)) -> 2.3096028
B11: p.04 | C11: Export gas price (NLNG, USD) | E11: $/Mscf | H11: =Timeline!H$18*Inputs!$D$47*(1+Inputs!$D$48)^MAX(0,Timeline!H$20-1) -> 0 | I11: =Timeline!I$18*Inputs!$D$47*(1+Inputs!$D$48)^MAX(0,Timeline!I$20-1) -> 0 | J11: =Timeline!J$18*Inputs!$D$47*(1+Inputs!$D$48)^MAX(0,Timeline!J$20-1) -> 0 | K11: =Timeline!K$18*Inputs!$D$47*(1+Inputs!$D$48)^MAX(0,Timeline!K$20-1) -> 0 | L11: =Timeline!L$18*Inputs!$D$47*(1+Inputs!$D$48)^MAX(0,Timeline!L$20-1) -> 0 | M11: =Timeline!M$18*Inputs!$D$47*(1+Inputs!$D$48)^MAX(0,Timeline!M$20-1) -> 0 | N11: =Timeline!N$18*Inputs!$D$47*(1+Inputs!$D$48)^MAX(0,Timeline!N$20-1) -> 0 | O11: =Timeline!O$18*Inputs!$D$47*(1+Inputs!$D$48)^MAX(0,Timeline!O$20-1) -> 0 | ... AQ11: =Timeline!AQ$18*Inputs!$D$47*(1+Inputs!$D$48)^MAX(0,Timeline!AQ$20-1) -> 3.2393596
B12: p.05 | C12: Brent | E12: $/bbl | H12: =Timeline!H$18*Inputs!$D$46 -> 0 | I12: =Timeline!I$18*Inputs!$D$46 -> 0 | J12: =Timeline!J$18*Inputs!$D$46 -> 0 | K12: =Timeline!K$18*Inputs!$D$46 -> 0 | L12: =Timeline!L$18*Inputs!$D$46 -> 0 | M12: =Timeline!M$18*Inputs!$D$46 -> 0 | N12: =Timeline!N$18*Inputs!$D$46 -> 0 | O12: =Timeline!O$18*Inputs!$D$46 -> 0 | ... AQ12: =Timeline!AQ$18*Inputs!$D$46 -> 65
B13: p.06 | C13: Condensate price | E13: $/bbl | H13: =Timeline!H$18*(Inputs!$D$46+Inputs!$D$49) -> 0 | I13: =Timeline!I$18*(Inputs!$D$46+Inputs!$D$49) -> 0 | J13: =Timeline!J$18*(Inputs!$D$46+Inputs!$D$49) -> 0 | K13: =Timeline!K$18*(Inputs!$D$46+Inputs!$D$49) -> 0 | L13: =Timeline!L$18*(Inputs!$D$46+Inputs!$D$49) -> 0 | M13: =Timeline!M$18*(Inputs!$D$46+Inputs!$D$49) -> 0 | N13: =Timeline!N$18*(Inputs!$D$46+Inputs!$D$49) -> 0 | O13: =Timeline!O$18*(Inputs!$D$46+Inputs!$D$49) -> 0 | ... AQ13: =Timeline!AQ$18*(Inputs!$D$46+Inputs!$D$49) -> 62
B14: p.07 | C14: LPG price | E14: $/bbl | H14: =Timeline!H$18*Inputs!$D$46*Inputs!$D$50 -> 0 | I14: =Timeline!I$18*Inputs!$D$46*Inputs!$D$50 -> 0 | J14: =Timeline!J$18*Inputs!$D$46*Inputs!$D$50 -> 0 | K14: =Timeline!K$18*Inputs!$D$46*Inputs!$D$50 -> 0 | L14: =Timeline!L$18*Inputs!$D$46*Inputs!$D$50 -> 0 | M14: =Timeline!M$18*Inputs!$D$46*Inputs!$D$50 -> 0 | N14: =Timeline!N$18*Inputs!$D$46*Inputs!$D$50 -> 0 | O14: =Timeline!O$18*Inputs!$D$46*Inputs!$D$50 -> 0 | ... AQ14: =Timeline!AQ$18*Inputs!$D$46*Inputs!$D$50 -> 39
B16: B. REVENUE
B17: p.10 | C17: Domestic gas revenue | D17: =SUM($H17:$AQ17) -> 1620.1618 | E17: $m | H17: =Throughput!H$30*H10/1000 -> 0 | I17: =Throughput!I$30*I10/1000 -> 0 | J17: =Throughput!J$30*J10/1000 -> 0 | K17: =Throughput!K$30*K10/1000 -> 0 | L17: =Throughput!L$30*L10/1000 -> 0 | M17: =Throughput!M$30*M10/1000 -> 0 | N17: =Throughput!N$30*N10/1000 -> 0 | O17: =Throughput!O$30*O10/1000 -> 0 | ... AQ17: =Throughput!AQ$30*AQ10/1000 -> 75.89909
B18: p.11 | C18: Export gas revenue (NLNG) | D18: =SUM($H18:$AQ18) -> 657.37366 | E18: $m | H18: =Throughput!H$31*H11/1000 -> 0 | I18: =Throughput!I$31*I11/1000 -> 0 | J18: =Throughput!J$31*J11/1000 -> 0 | K18: =Throughput!K$31*K11/1000 -> 0 | L18: =Throughput!L$31*L11/1000 -> 0 | M18: =Throughput!M$31*M11/1000 -> 0 | N18: =Throughput!N$31*N11/1000 -> 0 | O18: =Throughput!O$31*O11/1000 -> 0 | ... AQ18: =Throughput!AQ$31*AQ11/1000 -> 33.378361
B19: p.12 | C19: Condensate revenue | D19: =SUM($H19:$AQ19) -> 2586.3827 | E19: $m | H19: =Throughput!H$33*H13/1000 -> 0 | I19: =Throughput!I$33*I13/1000 -> 0 | J19: =Throughput!J$33*J13/1000 -> 0 | K19: =Throughput!K$33*K13/1000 -> 0 | L19: =Throughput!L$33*L13/1000 -> 0 | M19: =Throughput!M$33*M13/1000 -> 0 | N19: =Throughput!N$33*N13/1000 -> 0 | O19: =Throughput!O$33*O13/1000 -> 0 | ... AQ19: =Throughput!AQ$33*AQ13/1000 -> 128.46321
B20: p.13 | C20: LPG revenue | D20: =SUM($H20:$AQ20) -> 271.15302 | E20: $m | H20: =Throughput!H$34*H14/1000 -> 0 | I20: =Throughput!I$34*I14/1000 -> 0 | J20: =Throughput!J$34*J14/1000 -> 0 | K20: =Throughput!K$34*K14/1000 -> 0 | L20: =Throughput!L$34*L14/1000 -> 0 | M20: =Throughput!M$34*M14/1000 -> 0 | N20: =Throughput!N$34*N14/1000 -> 0 | O20: =Throughput!O$34*O14/1000 -> 0 | ... AQ20: =Throughput!AQ$34*AQ14/1000 -> 13.467917
B21: p.14 | C21: Total revenue | D21: =SUM($H21:$AQ21) -> 5135.0711 | E21: $m | H21: =SUM(H17:H20) -> 0 | I21: =SUM(I17:I20) -> 0 | J21: =SUM(J17:J20) -> 0 | K21: =SUM(K17:K20) -> 0 | L21: =SUM(L17:L20) -> 0 | M21: =SUM(M17:M20) -> 0 | N21: =SUM(N17:N20) -> 0 | O21: =SUM(O17:O20) -> 0 | ... AQ21: =SUM(AQ17:AQ20) -> 251.20857
B22: p.15 | C22: Gas share of revenue | D22: =IFERROR(AVERAGE($H22:$AQ22),0) -> 0.2967718 | E22: % | H22: =IF(H21=0,0,(H17+H18)/H21) -> 0 | I22: =IF(I21=0,0,(I17+I18)/I21) -> 0 | J22: =IF(J21=0,0,(J17+J18)/J21) -> 0 | K22: =IF(K21=0,0,(K17+K18)/K21) -> 0 | L22: =IF(L21=0,0,(L17+L18)/L21) -> 0 | M22: =IF(M21=0,0,(M17+M18)/M21) -> 0 | N22: =IF(N21=0,0,(N17+N18)/N21) -> 0 | O22: =IF(O21=0,0,(O17+O18)/O21) -> 0 | ... AQ22: =IF(AQ21=0,0,(AQ17+AQ18)/AQ21) -> 0.43500685
B23: p.16 | C23: Naira-denominated share of revenue | D23: =IFERROR(AVERAGE($H23:$AQ23),0) -> 0.21429437 | E23: % | H23: =IF(H21=0,0,H17*Inputs!$D$99/H21) -> 0 | I23: =IF(I21=0,0,I17*Inputs!$D$99/I21) -> 0 | J23: =IF(J21=0,0,J17*Inputs!$D$99/J21) -> 0 | K23: =IF(K21=0,0,K17*Inputs!$D$99/K21) -> 0 | L23: =IF(L21=0,0,L17*Inputs!$D$99/L21) -> 0 | M23: =IF(M21=0,0,M17*Inputs!$D$99/M21) -> 0 | N23: =IF(N21=0,0,N17*Inputs!$D$99/N21) -> 0 | O23: =IF(O21=0,0,O17*Inputs!$D$99/O21) -> 0 | ... AQ23: =IF(AQ21=0,0,AQ17*Inputs!$D$99/AQ21) -> 0.30213575
C25: Line p.03 is where Nigerian currency risk enters the project. With a 60% pass-through and 8% annual depreciation, the dollar value of domestic gas revenue falls roughly 3% a year in real terms even with the naira price rising. Scenario 4 combines a 35% pass-through with 25% depreciation, which is the genuine tail risk for a dollar-debt, naira-revenue project.

Sheet Opex
B2: FEEDSTOCK & OPERATING COSTS
B3: Wet gas is bought from the OML 53 upstream joint venture and priced as a share of AGPC's total product revenue. Everything below it is largely fixed, which is what drives the operating leverage at low throughput.
D6: Total | E6: Unit | H6: =Timeline!H$10 -> H1 2020 | I6: =Timeline!I$10 -> H2 2020 | J6: =Timeline!J$10 -> H1 2021 | K6: =Timeline!K$10 -> H2 2021 | L6: =Timeline!L$10 -> H1 2022 | M6: =Timeline!M$10 -> H2 2022 | N6: =Timeline!N$10 -> H1 2023 | O6: =Timeline!O$10 -> H2 2023 | ... AQ6: =Timeline!AQ$10 -> H2 2037
B7: x.00 | C7: Cost escalation index | E7: x | H7: =(1+Inputs!$D$62)^MAX(0,Timeline!H$20-1) -> 1 | I7: =(1+Inputs!$D$62)^MAX(0,Timeline!I$20-1) -> 1 | J7: =(1+Inputs!$D$62)^MAX(0,Timeline!J$20-1) -> 1 | K7: =(1+Inputs!$D$62)^MAX(0,Timeline!K$20-1) -> 1 | L7: =(1+Inputs!$D$62)^MAX(0,Timeline!L$20-1) -> 1 | M7: =(1+Inputs!$D$62)^MAX(0,Timeline!M$20-1) -> 1 | N7: =(1+Inputs!$D$62)^MAX(0,Timeline!N$20-1) -> 1 | O7: =(1+Inputs!$D$62)^MAX(0,Timeline!O$20-1) -> 1 | ... AQ7: =(1+Inputs!$D$62)^MAX(0,Timeline!AQ$20-1) -> 1.3842339
B8: x.01 | C8: Wet gas feedstock cost | D8: =SUM($H8:$AQ8) -> 2824.2891 | E8: $m | H8: =Revenue!H$21*Inputs!$D$56 -> 0 | I8: =Revenue!I$21*Inputs!$D$56 -> 0 | J8: =Revenue!J$21*Inputs!$D$56 -> 0 | K8: =Revenue!K$21*Inputs!$D$56 -> 0 | L8: =Revenue!L$21*Inputs!$D$56 -> 0 | M8: =Revenue!M$21*Inputs!$D$56 -> 0 | N8: =Revenue!N$21*Inputs!$D$56 -> 0 | O8: =Revenue!O$21*Inputs!$D$56 -> 0 | ... AQ8: =Revenue!AQ$21*Inputs!$D$56 -> 138.16472
B9: x.02 | C9: Fixed O&M | D9: =SUM($H9:$AQ9) -> 497.06613 | E9: $m | H9: =Timeline!H$18*Inputs!$D$57*H7*Timeline!H$14 -> 0 | I9: =Timeline!I$18*Inputs!$D$57*I7*Timeline!I$14 -> 0 | J9: =Timeline!J$18*Inputs!$D$57*J7*Timeline!J$14 -> 0 | K9: =Timeline!K$18*Inputs!$D$57*K7*Timeline!K$14 -> 0 | L9: =Timeline!L$18*Inputs!$D$57*L7*Timeline!L$14 -> 0 | M9: =Timeline!M$18*Inputs!$D$57*M7*Timeline!M$14 -> 0 | N9: =Timeline!N$18*Inputs!$D$57*N7*Timeline!N$14 -> 0 | O9: =Timeline!O$18*Inputs!$D$57*O7*Timeline!O$14 -> 0 | ... AQ9: =Timeline!AQ$18*Inputs!$D$57*AQ7*Timeline!AQ$14 -> 24.423195
